2021-10-19 10:51:47,657,aiogram.dispatcher.dispatcher[LINE:357] - Start polling.
2021-10-19 10:51:48,054,aiogram.dispatcher.dispatcher[LINE:357] - Start polling.
2021-10-19 10:52:02,252,aiogram.dispatcher.dispatcher[LINE:404] - Polling is stopped.
2021-10-19 10:52:02,257,aiogram.dispatcher.dispatcher[LINE:404] - Polling is stopped.
2021-10-19 10:52:02,262,__main__[LINE:82] - Bot stopped!
2021-10-19 10:52:02,661,aiogram.dispatcher.dispatcher[LINE:432] - Stop polling...
2021-10-19 10:52:02,669,aiogram.dispatcher.dispatcher[LINE:432] - Stop polling...
2021-10-19 10:52:05,988,aiogram.dispatcher.dispatcher[LINE:357] - Start polling.
2021-10-19 10:52:06,087,aiogram.dispatcher.dispatcher[LINE:357] - Start polling.
2021-10-19 10:53:10,085,handlers.receive_message[LINE:52] - Cancelling chat
2021-10-19 11:09:12,061,aiogram.dispatcher.dispatcher[LINE:404] - Polling is stopped.
2021-10-19 11:09:12,064,aiogram.dispatcher.dispatcher[LINE:404] - Polling is stopped.
2021-10-19 11:09:12,069,__main__[LINE:82] - Bot stopped!
2021-10-19 11:09:12,342,aiogram.dispatcher.dispatcher[LINE:432] - Stop polling...
2021-10-19 11:09:12,347,aiogram.dispatcher.dispatcher[LINE:432] - Stop polling...
2021-10-19 11:09:17,075,aiogram.dispatcher.dispatcher[LINE:357] - Start polling.
2021-10-19 11:09:17,406,aiogram.dispatcher.dispatcher[LINE:357] - Start polling.
2021-10-19 11:12:29,850,aiogram.dispatcher.dispatcher[LINE:404] - Polling is stopped.
2021-10-19 11:12:29,851,aiogram.dispatcher.dispatcher[LINE:404] - Polling is stopped.
2021-10-19 11:12:29,864,__main__[LINE:82] - Bot stopped!
2021-10-19 11:12:30,150,aiogram.dispatcher.dispatcher[LINE:432] - Stop polling...
2021-10-19 11:12:30,150,aiogram.dispatcher.dispatcher[LINE:432] - Stop polling...
2021-10-19 11:12:33,897,aiogram.dispatcher.dispatcher[LINE:357] - Start polling.
2021-10-19 11:12:34,100,aiogram.dispatcher.dispatcher[LINE:357] - Start polling.
2021-10-19 11:17:56,438,handlers.receive_message[LINE:52] - Cancelling chat
2021-10-19 11:19:51,650,handlers.receive_message[LINE:52] - Cancelling chat
2021-10-19 11:20:48,159,handlers.fsm_add_event[LINE:133] - Cancelling state 'Form:chat_data'
2021-10-19 11:20:48,226,asyncio[LINE:44] - Task exception was never retrieved
future: <Task finished name='Task-717' coro=<Dispatcher._process_polling_updates() done, defined at /home/bot/Documents/tb-engine/lib/python3.8/site-packages/aiogram/dispatcher/dispatcher.py:406> exception=BadRequest('Unsupported parse_mode')>
Traceback (most recent call last):
  File "/home/bot/Documents/tb-engine/lib/python3.8/site-packages/aiogram/dispatcher/dispatcher.py", line 414, in _process_polling_updates
    for responses in itertools.chain.from_iterable(await self.process_updates(updates, fast)):
  File "/home/bot/Documents/tb-engine/lib/python3.8/site-packages/aiogram/dispatcher/dispatcher.py", line 236, in process_updates
    return await asyncio.gather(*tasks)
  File "/home/bot/Documents/tb-engine/lib/python3.8/site-packages/aiogram/dispatcher/handler.py", line 116, in notify
    response = await handler_obj.handler(*args, **partial_data)
  File "/home/bot/Documents/tb-engine/lib/python3.8/site-packages/aiogram/dispatcher/dispatcher.py", line 257, in process_update
    return await self.message_handlers.notify(update.message)
  File "/home/bot/Documents/tb-engine/lib/python3.8/site-packages/aiogram/dispatcher/handler.py", line 116, in notify
    response = await handler_obj.handler(*args, **partial_data)
  File "/home/bot/Documents/test-client-service-bot/handlers/fsm_add_event.py", line 136, in cancel_handler
    await message.reply('Cancelled.', keyb.keyboard_reply_get(keyb.KEYBOARD_MAIN))
  File "/home/bot/Documents/tb-engine/lib/python3.8/site-packages/aiogram/types/message.py", line 1502, in reply
    return await self.bot.send_message(
  File "/home/bot/Documents/tb-engine/lib/python3.8/site-packages/aiogram/bot/bot.py", line 314, in send_message
    result = await self.request(api.Methods.SEND_MESSAGE, payload)
  File "/home/bot/Documents/tb-engine/lib/python3.8/site-packages/aiogram/bot/base.py", line 208, in request
    return await api.make_request(self.session, self.server, self.__token, method, data, files,
  File "/home/bot/Documents/tb-engine/lib/python3.8/site-packages/aiogram/bot/api.py", line 140, in make_request
    return check_result(method, response.content_type, response.status, await response.text())
  File "/home/bot/Documents/tb-engine/lib/python3.8/site-packages/aiogram/bot/api.py", line 115, in check_result
    exceptions.BadRequest.detect(description)
  File "/home/bot/Documents/tb-engine/lib/python3.8/site-packages/aiogram/utils/exceptions.py", line 141, in detect
    raise cls(description)
aiogram.utils.exceptions.BadRequest: Unsupported parse_mode
2021-10-19 13:55:10,151,handlers.receive_message[LINE:52] - Cancelling chat
2021-10-19 13:58:31,791,handlers.receive_message[LINE:52] - Cancelling chat
2021-10-19 13:59:07,039,aiogram.dispatcher.dispatcher[LINE:404] - Polling is stopped.
2021-10-19 13:59:07,039,aiogram.dispatcher.dispatcher[LINE:404] - Polling is stopped.
2021-10-19 13:59:07,045,__main__[LINE:82] - Bot stopped!
2021-10-19 13:59:07,366,aiogram.dispatcher.dispatcher[LINE:432] - Stop polling...
2021-10-19 13:59:07,367,aiogram.dispatcher.dispatcher[LINE:432] - Stop polling...
2021-10-19 14:54:59,364,aiogram.dispatcher.dispatcher[LINE:357] - Start polling.
2021-10-19 14:54:59,537,aiogram.dispatcher.dispatcher[LINE:357] - Start polling.
2021-10-19 15:11:16,246,aiogram.dispatcher.dispatcher[LINE:389] - Cause exception while getting updates.
Traceback (most recent call last):
  File "/home/bot/Documents/tb-engine/lib/python3.8/site-packages/aiogram/dispatcher/dispatcher.py", line 380, in start_polling
    updates = await self.bot.get_updates(
  File "/home/bot/Documents/tb-engine/lib/python3.8/site-packages/aiogram/bot/bot.py", line 97, in get_updates
    result = await self.request(api.Methods.GET_UPDATES, payload)
  File "/home/bot/Documents/tb-engine/lib/python3.8/site-packages/aiogram/bot/base.py", line 208, in request
    return await api.make_request(self.session, self.server, self.__token, method, data, files,
  File "/home/bot/Documents/tb-engine/lib/python3.8/site-packages/aiogram/bot/api.py", line 139, in make_request
    async with session.post(url, data=req, **kwargs) as response:
  File "/home/bot/Documents/tb-engine/lib/python3.8/site-packages/aiohttp/client.py", line 1117, in __aenter__
    self._resp = await self._coro
  File "/home/bot/Documents/tb-engine/lib/python3.8/site-packages/aiohttp/client.py", line 544, in _request
    await resp.start(conn)
  File "/home/bot/Documents/tb-engine/lib/python3.8/site-packages/aiohttp/client_reqrep.py", line 905, in start
    self._continue = None
  File "/home/bot/Documents/tb-engine/lib/python3.8/site-packages/aiohttp/helpers.py", line 656, in __exit__
    raise asyncio.TimeoutError from None
asyncio.exceptions.TimeoutError
2021-10-19 15:13:22,204,handlers.fsm_add_event[LINE:133] - Cancelling state 'Form:chat_data'
2021-10-19 15:13:22,217,asyncio[LINE:44] - Task exception was never retrieved
future: <Task finished name='Task-501' coro=<Dispatcher._process_polling_updates() done, defined at /home/bot/Documents/tb-engine/lib/python3.8/site-packages/aiogram/dispatcher/dispatcher.py:406> exception=TypeError("answer() got multiple values for argument 'parse_mode'")>
Traceback (most recent call last):
  File "/home/bot/Documents/tb-engine/lib/python3.8/site-packages/aiogram/dispatcher/dispatcher.py", line 414, in _process_polling_updates
    for responses in itertools.chain.from_iterable(await self.process_updates(updates, fast)):
  File "/home/bot/Documents/tb-engine/lib/python3.8/site-packages/aiogram/dispatcher/dispatcher.py", line 236, in process_updates
    return await asyncio.gather(*tasks)
  File "/home/bot/Documents/tb-engine/lib/python3.8/site-packages/aiogram/dispatcher/handler.py", line 116, in notify
    response = await handler_obj.handler(*args, **partial_data)
  File "/home/bot/Documents/tb-engine/lib/python3.8/site-packages/aiogram/dispatcher/dispatcher.py", line 257, in process_update
    return await self.message_handlers.notify(update.message)
  File "/home/bot/Documents/tb-engine/lib/python3.8/site-packages/aiogram/dispatcher/handler.py", line 116, in notify
    response = await handler_obj.handler(*args, **partial_data)
  File "/home/bot/Documents/test-client-service-bot/handlers/fsm_add_event.py", line 136, in cancel_handler
    await message.answer("Cancelled.", keyb.keyboard_reply_get(keyb.KEYBOARD_MAIN), parse_mode="HTML")
TypeError: answer() got multiple values for argument 'parse_mode'
2021-10-19 15:21:11,155,handlers.fsm_add_event[LINE:133] - Cancelling state 'Form:chat_data'
2021-10-19 15:21:11,156,asyncio[LINE:44] - Task exception was never retrieved
future: <Task finished name='Task-955' coro=<Dispatcher._process_polling_updates() done, defined at /home/bot/Documents/tb-engine/lib/python3.8/site-packages/aiogram/dispatcher/dispatcher.py:406> exception=TypeError("answer() got multiple values for argument 'parse_mode'")>
Traceback (most recent call last):
  File "/home/bot/Documents/tb-engine/lib/python3.8/site-packages/aiogram/dispatcher/dispatcher.py", line 414, in _process_polling_updates
    for responses in itertools.chain.from_iterable(await self.process_updates(updates, fast)):
  File "/home/bot/Documents/tb-engine/lib/python3.8/site-packages/aiogram/dispatcher/dispatcher.py", line 236, in process_updates
    return await asyncio.gather(*tasks)
  File "/home/bot/Documents/tb-engine/lib/python3.8/site-packages/aiogram/dispatcher/handler.py", line 116, in notify
    response = await handler_obj.handler(*args, **partial_data)
  File "/home/bot/Documents/tb-engine/lib/python3.8/site-packages/aiogram/dispatcher/dispatcher.py", line 257, in process_update
    return await self.message_handlers.notify(update.message)
  File "/home/bot/Documents/tb-engine/lib/python3.8/site-packages/aiogram/dispatcher/handler.py", line 116, in notify
    response = await handler_obj.handler(*args, **partial_data)
  File "/home/bot/Documents/test-client-service-bot/handlers/fsm_add_event.py", line 136, in cancel_handler
    await message.answer("Cancelled.", keyb.keyboard_reply_get(keyb.KEYBOARD_MAIN), parse_mode="HTML")
TypeError: answer() got multiple values for argument 'parse_mode'
2021-10-19 15:45:31,234,aiogram.dispatcher.dispatcher[LINE:389] - Cause exception while getting updates.
Traceback (most recent call last):
  File "/home/bot/Documents/tb-engine/lib/python3.8/site-packages/aiogram/dispatcher/dispatcher.py", line 380, in start_polling
    updates = await self.bot.get_updates(
  File "/home/bot/Documents/tb-engine/lib/python3.8/site-packages/aiogram/bot/bot.py", line 97, in get_updates
    result = await self.request(api.Methods.GET_UPDATES, payload)
  File "/home/bot/Documents/tb-engine/lib/python3.8/site-packages/aiogram/bot/base.py", line 208, in request
    return await api.make_request(self.session, self.server, self.__token, method, data, files,
  File "/home/bot/Documents/tb-engine/lib/python3.8/site-packages/aiogram/bot/api.py", line 139, in make_request
    async with session.post(url, data=req, **kwargs) as response:
  File "/home/bot/Documents/tb-engine/lib/python3.8/site-packages/aiohttp/client.py", line 1117, in __aenter__
    self._resp = await self._coro
  File "/home/bot/Documents/tb-engine/lib/python3.8/site-packages/aiohttp/client.py", line 544, in _request
    await resp.start(conn)
  File "/home/bot/Documents/tb-engine/lib/python3.8/site-packages/aiohttp/client_reqrep.py", line 905, in start
    self._continue = None
  File "/home/bot/Documents/tb-engine/lib/python3.8/site-packages/aiohttp/helpers.py", line 656, in __exit__
    raise asyncio.TimeoutError from None
asyncio.exceptions.TimeoutError
2021-10-19 16:00:07,507,aiogram.dispatcher.dispatcher[LINE:389] - Cause exception while getting updates.
Traceback (most recent call last):
  File "/home/bot/Documents/tb-engine/lib/python3.8/site-packages/aiogram/dispatcher/dispatcher.py", line 380, in start_polling
    updates = await self.bot.get_updates(
  File "/home/bot/Documents/tb-engine/lib/python3.8/site-packages/aiogram/bot/bot.py", line 97, in get_updates
    result = await self.request(api.Methods.GET_UPDATES, payload)
  File "/home/bot/Documents/tb-engine/lib/python3.8/site-packages/aiogram/bot/base.py", line 208, in request
    return await api.make_request(self.session, self.server, self.__token, method, data, files,
  File "/home/bot/Documents/tb-engine/lib/python3.8/site-packages/aiogram/bot/api.py", line 139, in make_request
    async with session.post(url, data=req, **kwargs) as response:
  File "/home/bot/Documents/tb-engine/lib/python3.8/site-packages/aiohttp/client.py", line 1117, in __aenter__
    self._resp = await self._coro
  File "/home/bot/Documents/tb-engine/lib/python3.8/site-packages/aiohttp/client.py", line 544, in _request
    await resp.start(conn)
  File "/home/bot/Documents/tb-engine/lib/python3.8/site-packages/aiohttp/client_reqrep.py", line 905, in start
    self._continue = None
  File "/home/bot/Documents/tb-engine/lib/python3.8/site-packages/aiohttp/helpers.py", line 656, in __exit__
    raise asyncio.TimeoutError from None
asyncio.exceptions.TimeoutError
2021-10-19 16:03:13,912,aiogram.dispatcher.dispatcher[LINE:404] - Polling is stopped.
2021-10-19 16:03:13,914,aiogram.dispatcher.dispatcher[LINE:404] - Polling is stopped.
2021-10-19 16:03:13,924,__main__[LINE:82] - Bot stopped!
2021-10-19 16:03:14,234,aiogram.dispatcher.dispatcher[LINE:432] - Stop polling...
2021-10-19 16:03:14,235,aiogram.dispatcher.dispatcher[LINE:432] - Stop polling...
2021-10-19 16:03:24,735,aiogram.dispatcher.dispatcher[LINE:357] - Start polling.
2021-10-19 16:03:25,162,aiogram.dispatcher.dispatcher[LINE:357] - Start polling.
2021-10-19 16:05:03,933,aiogram.dispatcher.dispatcher[LINE:404] - Polling is stopped.
2021-10-19 16:05:03,936,aiogram.dispatcher.dispatcher[LINE:404] - Polling is stopped.
2021-10-19 16:05:03,947,__main__[LINE:82] - Bot stopped!
2021-10-19 16:05:04,309,aiogram.dispatcher.dispatcher[LINE:432] - Stop polling...
2021-10-19 16:05:04,310,aiogram.dispatcher.dispatcher[LINE:432] - Stop polling...
2021-10-19 16:05:11,716,aiogram.dispatcher.dispatcher[LINE:357] - Start polling.
2021-10-19 16:05:11,919,aiogram.dispatcher.dispatcher[LINE:357] - Start polling.
2021-10-19 16:16:56,189,aiogram.dispatcher.dispatcher[LINE:389] - Cause exception while getting updates.
Traceback (most recent call last):
  File "/home/bot/Documents/tb-engine/lib/python3.8/site-packages/aiogram/dispatcher/dispatcher.py", line 380, in start_polling
    updates = await self.bot.get_updates(
  File "/home/bot/Documents/tb-engine/lib/python3.8/site-packages/aiogram/bot/bot.py", line 97, in get_updates
    result = await self.request(api.Methods.GET_UPDATES, payload)
  File "/home/bot/Documents/tb-engine/lib/python3.8/site-packages/aiogram/bot/base.py", line 208, in request
    return await api.make_request(self.session, self.server, self.__token, method, data, files,
  File "/home/bot/Documents/tb-engine/lib/python3.8/site-packages/aiogram/bot/api.py", line 139, in make_request
    async with session.post(url, data=req, **kwargs) as response:
  File "/home/bot/Documents/tb-engine/lib/python3.8/site-packages/aiohttp/client.py", line 1117, in __aenter__
    self._resp = await self._coro
  File "/home/bot/Documents/tb-engine/lib/python3.8/site-packages/aiohttp/client.py", line 544, in _request
    await resp.start(conn)
  File "/home/bot/Documents/tb-engine/lib/python3.8/site-packages/aiohttp/client_reqrep.py", line 905, in start
    self._continue = None
  File "/home/bot/Documents/tb-engine/lib/python3.8/site-packages/aiohttp/helpers.py", line 656, in __exit__
    raise asyncio.TimeoutError from None
asyncio.exceptions.TimeoutError
2021-10-19 16:16:56,261,aiogram.dispatcher.dispatcher[LINE:404] - Polling is stopped.
2021-10-19 16:16:56,262,aiogram.dispatcher.dispatcher[LINE:404] - Polling is stopped.
2021-10-19 16:16:56,271,__main__[LINE:80] - Bot stopped!
2021-10-19 16:16:56,879,aiogram.dispatcher.dispatcher[LINE:432] - Stop polling...
2021-10-19 16:16:56,887,aiogram.dispatcher.dispatcher[LINE:432] - Stop polling...
2021-10-19 16:18:40,073,aiogram.dispatcher.dispatcher[LINE:357] - Start polling.
2021-10-19 16:18:40,187,aiogram.dispatcher.dispatcher[LINE:357] - Start polling.
2021-10-19 16:20:38,560,aiogram.dispatcher.dispatcher[LINE:404] - Polling is stopped.
2021-10-19 16:20:38,570,aiogram.dispatcher.dispatcher[LINE:404] - Polling is stopped.
2021-10-19 16:20:38,590,__main__[LINE:82] - Bot stopped!
2021-10-19 16:20:38,999,aiogram.dispatcher.dispatcher[LINE:432] - Stop polling...
2021-10-19 16:20:38,999,aiogram.dispatcher.dispatcher[LINE:432] - Stop polling...
2021-10-19 16:27:58,667,aiogram.dispatcher.dispatcher[LINE:357] - Start polling.
2021-10-19 16:27:58,740,aiogram.dispatcher.dispatcher[LINE:357] - Start polling.
2021-10-19 16:39:19,918,aiogram.dispatcher.dispatcher[LINE:389] - Cause exception while getting updates.
Traceback (most recent call last):
  File "/home/bot/Documents/tb-engine/lib/python3.8/site-packages/aiogram/dispatcher/dispatcher.py", line 380, in start_polling
    updates = await self.bot.get_updates(
  File "/home/bot/Documents/tb-engine/lib/python3.8/site-packages/aiogram/bot/bot.py", line 97, in get_updates
    result = await self.request(api.Methods.GET_UPDATES, payload)
  File "/home/bot/Documents/tb-engine/lib/python3.8/site-packages/aiogram/bot/base.py", line 208, in request
    return await api.make_request(self.session, self.server, self.__token, method, data, files,
  File "/home/bot/Documents/tb-engine/lib/python3.8/site-packages/aiogram/bot/api.py", line 139, in make_request
    async with session.post(url, data=req, **kwargs) as response:
  File "/home/bot/Documents/tb-engine/lib/python3.8/site-packages/aiohttp/client.py", line 1117, in __aenter__
    self._resp = await self._coro
  File "/home/bot/Documents/tb-engine/lib/python3.8/site-packages/aiohttp/client.py", line 544, in _request
    await resp.start(conn)
  File "/home/bot/Documents/tb-engine/lib/python3.8/site-packages/aiohttp/client_reqrep.py", line 905, in start
    self._continue = None
  File "/home/bot/Documents/tb-engine/lib/python3.8/site-packages/aiohttp/helpers.py", line 656, in __exit__
    raise asyncio.TimeoutError from None
asyncio.exceptions.TimeoutError
2021-10-19 16:39:19,976,aiogram.dispatcher.dispatcher[LINE:404] - Polling is stopped.
2021-10-19 16:39:19,979,aiogram.dispatcher.dispatcher[LINE:404] - Polling is stopped.
2021-10-19 16:39:19,982,__main__[LINE:80] - Bot stopped!
2021-10-19 16:39:20,437,aiogram.dispatcher.dispatcher[LINE:432] - Stop polling...
2021-10-19 16:39:20,443,aiogram.dispatcher.dispatcher[LINE:432] - Stop polling...
2021-10-19 16:48:01,253,aiogram.dispatcher.dispatcher[LINE:357] - Start polling.
2021-10-19 16:48:01,881,aiogram.dispatcher.dispatcher[LINE:357] - Start polling.
2021-10-19 17:09:37,217,aiogram.dispatcher.dispatcher[LINE:389] - Cause exception while getting updates.
Traceback (most recent call last):
  File "/home/bot/Documents/tb-engine/lib/python3.8/site-packages/aiogram/dispatcher/dispatcher.py", line 380, in start_polling
    updates = await self.bot.get_updates(
  File "/home/bot/Documents/tb-engine/lib/python3.8/site-packages/aiogram/bot/bot.py", line 97, in get_updates
    result = await self.request(api.Methods.GET_UPDATES, payload)
  File "/home/bot/Documents/tb-engine/lib/python3.8/site-packages/aiogram/bot/base.py", line 208, in request
    return await api.make_request(self.session, self.server, self.__token, method, data, files,
  File "/home/bot/Documents/tb-engine/lib/python3.8/site-packages/aiogram/bot/api.py", line 139, in make_request
    async with session.post(url, data=req, **kwargs) as response:
  File "/home/bot/Documents/tb-engine/lib/python3.8/site-packages/aiohttp/client.py", line 1117, in __aenter__
    self._resp = await self._coro
  File "/home/bot/Documents/tb-engine/lib/python3.8/site-packages/aiohttp/client.py", line 544, in _request
    await resp.start(conn)
  File "/home/bot/Documents/tb-engine/lib/python3.8/site-packages/aiohttp/client_reqrep.py", line 905, in start
    self._continue = None
  File "/home/bot/Documents/tb-engine/lib/python3.8/site-packages/aiohttp/helpers.py", line 656, in __exit__
    raise asyncio.TimeoutError from None
asyncio.exceptions.TimeoutError
2021-10-19 17:09:37,618,__main__[LINE:82] - Bot stopped!
2021-10-19 17:10:00,513,aiogram.dispatcher.dispatcher[LINE:357] - Start polling.
2021-10-19 17:10:00,856,aiogram.dispatcher.dispatcher[LINE:357] - Start polling.
2021-10-19 17:13:13,741,asyncio[LINE:104] - Task exception was never retrieved
future: <Task finished name='Task-134' coro=<Dispatcher._process_polling_updates() done, defined at /home/bot/Documents/tb-engine/lib/python3.8/site-packages/aiogram/dispatcher/dispatcher.py:406> exception=AttributeError("'NoneType' object has no attribute 'split'")>
Traceback (most recent call last):
  File "/usr/lib/python3.8/asyncio/tasks.py", line 282, in __step
    result = coro.throw(exc)
  File "/home/bot/Documents/tb-engine/lib/python3.8/site-packages/aiogram/dispatcher/dispatcher.py", line 414, in _process_polling_updates
    for responses in itertools.chain.from_iterable(await self.process_updates(updates, fast)):
  File "/home/bot/Documents/tb-engine/lib/python3.8/site-packages/aiogram/dispatcher/dispatcher.py", line 236, in process_updates
    return await asyncio.gather(*tasks)
  File "/usr/lib/python3.8/asyncio/tasks.py", line 349, in __wakeup
    future.result()
  File "/usr/lib/python3.8/asyncio/tasks.py", line 280, in __step
    result = coro.send(None)
  File "/home/bot/Documents/tb-engine/lib/python3.8/site-packages/aiogram/dispatcher/handler.py", line 116, in notify
    response = await handler_obj.handler(*args, **partial_data)
  File "/home/bot/Documents/tb-engine/lib/python3.8/site-packages/aiogram/dispatcher/dispatcher.py", line 284, in process_update
    return await self.callback_query_handlers.notify(update.callback_query)
  File "/home/bot/Documents/tb-engine/lib/python3.8/site-packages/aiogram/dispatcher/handler.py", line 116, in notify
    response = await handler_obj.handler(*args, **partial_data)
  File "/home/bot/Documents/test-client-service-bot/handlers/receive_message.py", line 29, in connect_user
    event_id = query.message.caption.split(f'\n')[1]
AttributeError: 'NoneType' object has no attribute 'split'
2021-10-19 17:13:13,773,asyncio[LINE:104] - Task exception was never retrieved
future: <Task finished name='Task-234' coro=<Dispatcher._process_polling_updates() done, defined at /home/bot/Documents/tb-engine/lib/python3.8/site-packages/aiogram/dispatcher/dispatcher.py:406> exception=AttributeError("'NoneType' object has no attribute 'split'")>
Traceback (most recent call last):
  File "/usr/lib/python3.8/asyncio/tasks.py", line 282, in __step
    result = coro.throw(exc)
  File "/home/bot/Documents/tb-engine/lib/python3.8/site-packages/aiogram/dispatcher/dispatcher.py", line 414, in _process_polling_updates
    for responses in itertools.chain.from_iterable(await self.process_updates(updates, fast)):
  File "/home/bot/Documents/tb-engine/lib/python3.8/site-packages/aiogram/dispatcher/dispatcher.py", line 236, in process_updates
    return await asyncio.gather(*tasks)
  File "/usr/lib/python3.8/asyncio/tasks.py", line 349, in __wakeup
    future.result()
  File "/usr/lib/python3.8/asyncio/tasks.py", line 280, in __step
    result = coro.send(None)
  File "/home/bot/Documents/tb-engine/lib/python3.8/site-packages/aiogram/dispatcher/handler.py", line 116, in notify
    response = await handler_obj.handler(*args, **partial_data)
  File "/home/bot/Documents/tb-engine/lib/python3.8/site-packages/aiogram/dispatcher/dispatcher.py", line 257, in process_update
    return await self.message_handlers.notify(update.message)
  File "/home/bot/Documents/tb-engine/lib/python3.8/site-packages/aiogram/dispatcher/handler.py", line 116, in notify
    response = await handler_obj.handler(*args, **partial_data)
  File "/home/bot/Documents/test-client-service-bot/handlers/receive_message.py", line 108, in forward_text
    text_, chat_id_, keyboard, _ = await prepare_vars(message, state)
  File "/home/bot/Documents/test-client-service-bot/handlers/receive_message.py", line 64, in prepare_vars
    event_id = state_data['chat_data'].message.caption.split(f'\n')[0]
AttributeError: 'NoneType' object has no attribute 'split'
2021-10-19 17:15:37,979,handlers.fsm_add_event[LINE:133] - Cancelling state 'Form:chat_data'
2021-10-19 17:15:47,409,handlers.fsm_add_event[LINE:133] - Cancelling state 'Form:event_name'
2021-10-19 17:16:26,944,__main__[LINE:82] - Bot stopped!
2021-10-19 17:16:27,519,asyncio[LINE:104] - Task exception was never retrieved
future: <Task finished name='Task-414' coro=<Dispatcher._process_polling_updates() done, defined at /home/bot/Documents/tb-engine/lib/python3.8/site-packages/aiogram/dispatcher/dispatcher.py:406> exception=AttributeError("'NoneType' object has no attribute 'split'")>
Traceback (most recent call last):
  File "/usr/lib/python3.8/asyncio/tasks.py", line 282, in __step
    result = coro.throw(exc)
  File "/home/bot/Documents/tb-engine/lib/python3.8/site-packages/aiogram/dispatcher/dispatcher.py", line 414, in _process_polling_updates
    for responses in itertools.chain.from_iterable(await self.process_updates(updates, fast)):
  File "/home/bot/Documents/tb-engine/lib/python3.8/site-packages/aiogram/dispatcher/dispatcher.py", line 236, in process_updates
    return await asyncio.gather(*tasks)
  File "/usr/lib/python3.8/asyncio/tasks.py", line 349, in __wakeup
    future.result()
  File "/usr/lib/python3.8/asyncio/tasks.py", line 280, in __step
    result = coro.send(None)
  File "/home/bot/Documents/tb-engine/lib/python3.8/site-packages/aiogram/dispatcher/handler.py", line 116, in notify
    response = await handler_obj.handler(*args, **partial_data)
  File "/home/bot/Documents/tb-engine/lib/python3.8/site-packages/aiogram/dispatcher/dispatcher.py", line 257, in process_update
    return await self.message_handlers.notify(update.message)
  File "/home/bot/Documents/tb-engine/lib/python3.8/site-packages/aiogram/dispatcher/handler.py", line 116, in notify
    response = await handler_obj.handler(*args, **partial_data)
  File "/home/bot/Documents/test-client-service-bot/handlers/receive_message.py", line 108, in forward_text
    text_, chat_id_, keyboard, _ = await prepare_vars(message, state)
  File "/home/bot/Documents/test-client-service-bot/handlers/receive_message.py", line 64, in prepare_vars
    event_id = state_data['chat_data'].message.caption.split(f'\n')[0]
AttributeError: 'NoneType' object has no attribute 'split'
2021-10-19 17:16:27,535,asyncio[LINE:104] - Task exception was never retrieved
future: <Task finished name='Task-427' coro=<Dispatcher._process_polling_updates() done, defined at /home/bot/Documents/tb-engine/lib/python3.8/site-packages/aiogram/dispatcher/dispatcher.py:406> exception=TypeError("answer() got multiple values for argument 'parse_mode'")>
Traceback (most recent call last):
  File "/usr/lib/python3.8/asyncio/tasks.py", line 282, in __step
    result = coro.throw(exc)
  File "/home/bot/Documents/tb-engine/lib/python3.8/site-packages/aiogram/dispatcher/dispatcher.py", line 414, in _process_polling_updates
    for responses in itertools.chain.from_iterable(await self.process_updates(updates, fast)):
  File "/home/bot/Documents/tb-engine/lib/python3.8/site-packages/aiogram/dispatcher/dispatcher.py", line 236, in process_updates
    return await asyncio.gather(*tasks)
  File "/usr/lib/python3.8/asyncio/tasks.py", line 349, in __wakeup
    future.result()
  File "/usr/lib/python3.8/asyncio/tasks.py", line 280, in __step
    result = coro.send(None)
  File "/home/bot/Documents/tb-engine/lib/python3.8/site-packages/aiogram/dispatcher/handler.py", line 116, in notify
    response = await handler_obj.handler(*args, **partial_data)
  File "/home/bot/Documents/tb-engine/lib/python3.8/site-packages/aiogram/dispatcher/dispatcher.py", line 257, in process_update
    return await self.message_handlers.notify(update.message)
  File "/home/bot/Documents/tb-engine/lib/python3.8/site-packages/aiogram/dispatcher/handler.py", line 116, in notify
    response = await handler_obj.handler(*args, **partial_data)
  File "/home/bot/Documents/test-client-service-bot/handlers/fsm_add_event.py", line 136, in cancel_handler
    await message.answer("Cancelled.", keyb.keyboard_reply_get(keyb.KEYBOARD_MAIN), parse_mode="HTML")
TypeError: answer() got multiple values for argument 'parse_mode'
2021-10-19 17:16:27,536,asyncio[LINE:104] - Task exception was never retrieved
future: <Task finished name='Task-450' coro=<Dispatcher._process_polling_updates() done, defined at /home/bot/Documents/tb-engine/lib/python3.8/site-packages/aiogram/dispatcher/dispatcher.py:406> exception=TypeError("answer() got multiple values for argument 'parse_mode'")>
Traceback (most recent call last):
  File "/usr/lib/python3.8/asyncio/tasks.py", line 282, in __step
    result = coro.throw(exc)
  File "/home/bot/Documents/tb-engine/lib/python3.8/site-packages/aiogram/dispatcher/dispatcher.py", line 414, in _process_polling_updates
    for responses in itertools.chain.from_iterable(await self.process_updates(updates, fast)):
  File "/home/bot/Documents/tb-engine/lib/python3.8/site-packages/aiogram/dispatcher/dispatcher.py", line 236, in process_updates
    return await asyncio.gather(*tasks)
  File "/usr/lib/python3.8/asyncio/tasks.py", line 349, in __wakeup
    future.result()
  File "/usr/lib/python3.8/asyncio/tasks.py", line 280, in __step
    result = coro.send(None)
  File "/home/bot/Documents/tb-engine/lib/python3.8/site-packages/aiogram/dispatcher/handler.py", line 116, in notify
    response = await handler_obj.handler(*args, **partial_data)
  File "/home/bot/Documents/tb-engine/lib/python3.8/site-packages/aiogram/dispatcher/dispatcher.py", line 257, in process_update
    return await self.message_handlers.notify(update.message)
  File "/home/bot/Documents/tb-engine/lib/python3.8/site-packages/aiogram/dispatcher/handler.py", line 116, in notify
    response = await handler_obj.handler(*args, **partial_data)
  File "/home/bot/Documents/test-client-service-bot/handlers/fsm_add_event.py", line 136, in cancel_handler
    await message.answer("Cancelled.", keyb.keyboard_reply_get(keyb.KEYBOARD_MAIN), parse_mode="HTML")
TypeError: answer() got multiple values for argument 'parse_mode'
2021-10-19 17:16:37,367,aiogram.dispatcher.dispatcher[LINE:357] - Start polling.
2021-10-19 17:16:37,633,aiogram.dispatcher.dispatcher[LINE:357] - Start polling.
2021-10-19 17:42:27,611,__main__[LINE:82] - Bot stopped!
2021-10-19 17:42:38,577,aiogram.dispatcher.dispatcher[LINE:357] - Start polling.
2021-10-19 17:42:38,915,aiogram.dispatcher.dispatcher[LINE:357] - Start polling.
2021-10-19 17:44:56,937,__main__[LINE:82] - Bot stopped!
2021-10-19 17:44:57,616,asyncio[LINE:104] - Task exception was never retrieved
future: <Task finished name='Task-26' coro=<Dispatcher._process_polling_updates() done, defined at /home/bot/Documents/tb-engine/lib/python3.8/site-packages/aiogram/dispatcher/dispatcher.py:406> exception=NetworkError('Aiohttp client throws an error: ClientConnectorError: Cannot connect to host api.telegram.org:443 ssl:default [Network is unreachable]')>
Traceback (most recent call last):
  File "/home/bot/Documents/tb-engine/lib/python3.8/site-packages/aiohttp/connector.py", line 969, in _wrap_create_connection
    return await self._loop.create_connection(*args, **kwargs)  # type: ignore  # noqa
  File "uvloop/loop.pyx", line 2024, in create_connection
  File "uvloop/loop.pyx", line 2000, in uvloop.loop.Loop.create_connection
  File "uvloop/handles/tcp.pyx", line 182, in uvloop.loop.TCPTransport.connect
  File "uvloop/handles/tcp.pyx", line 204, in uvloop.loop._TCPConnectRequest.connect
OSError: [Errno 101] Network is unreachable

The above exception was the direct cause of the following exception:

Traceback (most recent call last):
  File "/home/bot/Documents/tb-engine/lib/python3.8/site-packages/aiogram/bot/api.py", line 139, in make_request
    async with session.post(url, data=req, **kwargs) as response:
  File "/home/bot/Documents/tb-engine/lib/python3.8/site-packages/aiohttp/client.py", line 1117, in __aenter__
    self._resp = await self._coro
  File "/home/bot/Documents/tb-engine/lib/python3.8/site-packages/aiohttp/client.py", line 520, in _request
    conn = await self._connector.connect(
  File "/home/bot/Documents/tb-engine/lib/python3.8/site-packages/aiohttp/connector.py", line 535, in connect
    proto = await self._create_connection(req, traces, timeout)
  File "/home/bot/Documents/tb-engine/lib/python3.8/site-packages/aiohttp/connector.py", line 892, in _create_connection
    _, proto = await self._create_direct_connection(req, traces, timeout)
  File "/home/bot/Documents/tb-engine/lib/python3.8/site-packages/aiohttp/connector.py", line 1051, in _create_direct_connection
    raise last_exc
  File "/home/bot/Documents/tb-engine/lib/python3.8/site-packages/aiohttp/connector.py", line 1020, in _create_direct_connection
    transp, proto = await self._wrap_create_connection(
  File "/home/bot/Documents/tb-engine/lib/python3.8/site-packages/aiohttp/connector.py", line 975, in _wrap_create_connection
    raise client_error(req.connection_key, exc) from exc
aiohttp.client_exceptions.ClientConnectorError: Cannot connect to host api.telegram.org:443 ssl:default [Network is unreachable]

During handling of the above exception, another exception occurred:

Traceback (most recent call last):
  File "/usr/lib/python3.8/asyncio/tasks.py", line 282, in __step
    result = coro.throw(exc)
  File "/home/bot/Documents/tb-engine/lib/python3.8/site-packages/aiogram/dispatcher/dispatcher.py", line 414, in _process_polling_updates
    for responses in itertools.chain.from_iterable(await self.process_updates(updates, fast)):
  File "/home/bot/Documents/tb-engine/lib/python3.8/site-packages/aiogram/dispatcher/dispatcher.py", line 236, in process_updates
    return await asyncio.gather(*tasks)
  File "/usr/lib/python3.8/asyncio/tasks.py", line 349, in __wakeup
    future.result()
  File "/usr/lib/python3.8/asyncio/tasks.py", line 280, in __step
    result = coro.send(None)
  File "/home/bot/Documents/tb-engine/lib/python3.8/site-packages/aiogram/dispatcher/handler.py", line 116, in notify
    response = await handler_obj.handler(*args, **partial_data)
  File "/home/bot/Documents/tb-engine/lib/python3.8/site-packages/aiogram/dispatcher/dispatcher.py", line 257, in process_update
    return await self.message_handlers.notify(update.message)
  File "/home/bot/Documents/tb-engine/lib/python3.8/site-packages/aiogram/dispatcher/handler.py", line 116, in notify
    response = await handler_obj.handler(*args, **partial_data)
  File "/home/bot/Documents/test-client-service-bot/handlers/receive_message.py", line 110, in forward_text
    await message.bot.send_message(
  File "/home/bot/Documents/tb-engine/lib/python3.8/site-packages/aiogram/bot/bot.py", line 314, in send_message
    result = await self.request(api.Methods.SEND_MESSAGE, payload)
  File "/home/bot/Documents/tb-engine/lib/python3.8/site-packages/aiogram/bot/base.py", line 208, in request
    return await api.make_request(self.session, self.server, self.__token, method, data, files,
  File "/home/bot/Documents/tb-engine/lib/python3.8/site-packages/aiogram/bot/api.py", line 142, in make_request
    raise exceptions.NetworkError(f"aiohttp client throws an error: {e.__class__.__name__}: {e}")
aiogram.utils.exceptions.NetworkError: Aiohttp client throws an error: ClientConnectorError: Cannot connect to host api.telegram.org:443 ssl:default [Network is unreachable]
2021-10-19 17:48:59,658,aiogram.dispatcher.dispatcher[LINE:357] - Start polling.
2021-10-19 17:48:59,885,aiogram.dispatcher.dispatcher[LINE:357] - Start polling.
2021-10-19 18:04:59,625,aiogram.dispatcher.dispatcher[LINE:389] - Cause exception while getting updates.
Traceback (most recent call last):
  File "/home/bot/Documents/tb-engine/lib/python3.8/site-packages/aiogram/dispatcher/dispatcher.py", line 380, in start_polling
    updates = await self.bot.get_updates(
  File "/home/bot/Documents/tb-engine/lib/python3.8/site-packages/aiogram/bot/bot.py", line 97, in get_updates
    result = await self.request(api.Methods.GET_UPDATES, payload)
  File "/home/bot/Documents/tb-engine/lib/python3.8/site-packages/aiogram/bot/base.py", line 208, in request
    return await api.make_request(self.session, self.server, self.__token, method, data, files,
  File "/home/bot/Documents/tb-engine/lib/python3.8/site-packages/aiogram/bot/api.py", line 139, in make_request
    async with session.post(url, data=req, **kwargs) as response:
  File "/home/bot/Documents/tb-engine/lib/python3.8/site-packages/aiohttp/client.py", line 1117, in __aenter__
    self._resp = await self._coro
  File "/home/bot/Documents/tb-engine/lib/python3.8/site-packages/aiohttp/client.py", line 544, in _request
    await resp.start(conn)
  File "/home/bot/Documents/tb-engine/lib/python3.8/site-packages/aiohttp/client_reqrep.py", line 905, in start
    self._continue = None
  File "/home/bot/Documents/tb-engine/lib/python3.8/site-packages/aiohttp/helpers.py", line 656, in __exit__
    raise asyncio.TimeoutError from None
asyncio.exceptions.TimeoutError
2021-10-19 18:08:50,060,asyncio[LINE:104] - Task exception was never retrieved
future: <Task finished name='Task-325' coro=<Dispatcher._process_polling_updates() done, defined at /home/bot/Documents/tb-engine/lib/python3.8/site-packages/aiogram/dispatcher/dispatcher.py:406> exception=BadRequest('User not found')>
Traceback (most recent call last):
  File "/usr/lib/python3.8/asyncio/tasks.py", line 282, in __step
    result = coro.throw(exc)
  File "/home/bot/Documents/tb-engine/lib/python3.8/site-packages/aiogram/dispatcher/dispatcher.py", line 414, in _process_polling_updates
    for responses in itertools.chain.from_iterable(await self.process_updates(updates, fast)):
  File "/home/bot/Documents/tb-engine/lib/python3.8/site-packages/aiogram/dispatcher/dispatcher.py", line 236, in process_updates
    return await asyncio.gather(*tasks)
  File "/usr/lib/python3.8/asyncio/tasks.py", line 349, in __wakeup
    future.result()
  File "/usr/lib/python3.8/asyncio/tasks.py", line 280, in __step
    result = coro.send(None)
  File "/home/bot/Documents/tb-engine/lib/python3.8/site-packages/aiogram/dispatcher/handler.py", line 116, in notify
    response = await handler_obj.handler(*args, **partial_data)
  File "/home/bot/Documents/tb-engine/lib/python3.8/site-packages/aiogram/dispatcher/dispatcher.py", line 284, in process_update
    return await self.callback_query_handlers.notify(update.callback_query)
  File "/home/bot/Documents/tb-engine/lib/python3.8/site-packages/aiogram/dispatcher/handler.py", line 116, in notify
    response = await handler_obj.handler(*args, **partial_data)
  File "/home/bot/Documents/test-client-service-bot/handlers/receive_message.py", line 24, in connect_user
    async def connect_user(query: types.CallbackQuery, state: FSMContext):
  File "/home/bot/Documents/tb-engine/lib/python3.8/site-packages/aiogram/bot/bot.py", line 2187, in get_chat_member
    result = await self.request(api.Methods.GET_CHAT_MEMBER, payload)
  File "/home/bot/Documents/tb-engine/lib/python3.8/site-packages/aiogram/bot/base.py", line 208, in request
    return await api.make_request(self.session, self.server, self.__token, method, data, files,
  File "/home/bot/Documents/tb-engine/lib/python3.8/site-packages/aiogram/bot/api.py", line 140, in make_request
    return check_result(method, response.content_type, response.status, await response.text())
  File "/home/bot/Documents/tb-engine/lib/python3.8/site-packages/aiogram/bot/api.py", line 115, in check_result
    exceptions.BadRequest.detect(description)
  File "/home/bot/Documents/tb-engine/lib/python3.8/site-packages/aiogram/utils/exceptions.py", line 141, in detect
    raise cls(description)
aiogram.utils.exceptions.BadRequest: User not found
2021-10-19 18:09:08,195,handlers.fsm_add_event[LINE:133] - Cancelling state 'Form:chat_data'
2021-10-19 18:13:30,444,aiogram.dispatcher.dispatcher[LINE:357] - Start polling.
2021-10-19 18:13:30,525,aiogram.dispatcher.dispatcher[LINE:357] - Start polling.
2021-10-19 18:14:30,276,asyncio[LINE:32] - Executing <Task pending name='Task-51' coro=<Handler.notify() running at /home/bot/Documents/tb-engine/lib/python3.8/site-packages/aiogram/dispatcher/handler.py:116> wait_for=<Future pending cb=[shield.<locals>._outer_done_callback() at /usr/lib/python3.8/asyncio/tasks.py:902, Task.__wakeup()] created at /usr/lib/python3.8/asyncio/tasks.py:883> cb=[gather.<locals>._done_callback() at /usr/lib/python3.8/asyncio/tasks.py:769] created at /usr/lib/python3.8/asyncio/tasks.py:824> took 33.609 seconds
2021-10-19 18:14:32,820,asyncio[LINE:32] - Executing <Task finished name='Task-51' coro=<Handler.notify() done, defined at /home/bot/Documents/tb-engine/lib/python3.8/site-packages/aiogram/dispatcher/handler.py:84> result=[[]] created at /usr/lib/python3.8/asyncio/tasks.py:824> took 2.131 seconds
2021-10-19 18:32:02,190,aiogram.dispatcher.dispatcher[LINE:389] - Cause exception while getting updates.
Traceback (most recent call last):
  File "/home/bot/Documents/tb-engine/lib/python3.8/site-packages/aiogram/dispatcher/dispatcher.py", line 380, in start_polling
    updates = await self.bot.get_updates(
  File "/home/bot/Documents/tb-engine/lib/python3.8/site-packages/aiogram/bot/bot.py", line 97, in get_updates
    result = await self.request(api.Methods.GET_UPDATES, payload)
  File "/home/bot/Documents/tb-engine/lib/python3.8/site-packages/aiogram/bot/base.py", line 208, in request
    return await api.make_request(self.session, self.server, self.__token, method, data, files,
  File "/home/bot/Documents/tb-engine/lib/python3.8/site-packages/aiogram/bot/api.py", line 139, in make_request
    async with session.post(url, data=req, **kwargs) as response:
  File "/home/bot/Documents/tb-engine/lib/python3.8/site-packages/aiohttp/client.py", line 1117, in __aenter__
    self._resp = await self._coro
  File "/home/bot/Documents/tb-engine/lib/python3.8/site-packages/aiohttp/client.py", line 544, in _request
    await resp.start(conn)
  File "/home/bot/Documents/tb-engine/lib/python3.8/site-packages/aiohttp/client_reqrep.py", line 905, in start
    self._continue = None
  File "/home/bot/Documents/tb-engine/lib/python3.8/site-packages/aiohttp/helpers.py", line 656, in __exit__
    raise asyncio.TimeoutError from None
asyncio.exceptions.TimeoutError
2021-10-19 18:32:02,251,__main__[LINE:80] - Bot stopped!
2021-10-19 18:32:17,961,aiogram.dispatcher.dispatcher[LINE:357] - Start polling.
2021-10-19 18:32:18,849,aiogram.dispatcher.dispatcher[LINE:357] - Start polling.
2021-10-19 18:38:29,250,asyncio[LINE:1707] - Task exception was never retrieved
future: <Task finished name='Task-80' coro=<Dispatcher._process_polling_updates() done, defined at /home/bot/Documents/tb-engine/lib/python3.8/site-packages/aiogram/dispatcher/dispatcher.py:406> exception=BadRequest('User not found') created at /usr/lib/python3.8/asyncio/tasks.py:382>
source_traceback: Object created at (most recent call last):
  File "/usr/lib/python3.8/asyncio/events.py", line 81, in _run
    self._context.run(self._callback, *self._args)
  File "/usr/lib/python3.8/asyncio/tasks.py", line 360, in __wakeup
    self.__step()
  File "/home/bot/.local/share/JetBrains/PyCharmCE2021.2/evaluate-async-code/_pydevd_async_debug.py", line 169, in step
    step_orig(task, exc)
  File "/usr/lib/python3.8/asyncio/tasks.py", line 280, in __step
    result = coro.send(None)
  File "/home/bot/Documents/test-client-service-bot/main__.py", line 30, in start_service_bot
    await dp.start_polling(dp)
  File "/home/bot/Documents/tb-engine/lib/python3.8/site-packages/aiogram/dispatcher/dispatcher.py", line 397, in start_polling
    self._loop_create_task(self._process_polling_updates(updates, fast))
  File "/home/bot/Documents/tb-engine/lib/python3.8/site-packages/aiogram/dispatcher/dispatcher.py", line 330, in _loop_create_task
    return asyncio.create_task(coro)
  File "/usr/lib/python3.8/asyncio/tasks.py", line 382, in create_task
    task = loop.create_task(coro)
Traceback (most recent call last):
  File "/usr/lib/python3.8/asyncio/tasks.py", line 282, in __step
    result = coro.throw(exc)
  File "/home/bot/Documents/tb-engine/lib/python3.8/site-packages/aiogram/dispatcher/dispatcher.py", line 414, in _process_polling_updates
    for responses in itertools.chain.from_iterable(await self.process_updates(updates, fast)):
  File "/home/bot/Documents/tb-engine/lib/python3.8/site-packages/aiogram/dispatcher/dispatcher.py", line 236, in process_updates
    return await asyncio.gather(*tasks)
  File "/usr/lib/python3.8/asyncio/tasks.py", line 349, in __wakeup
    future.result()
  File "/usr/lib/python3.8/asyncio/tasks.py", line 280, in __step
    result = coro.send(None)
  File "/home/bot/Documents/tb-engine/lib/python3.8/site-packages/aiogram/dispatcher/handler.py", line 116, in notify
    response = await handler_obj.handler(*args, **partial_data)
  File "/home/bot/Documents/tb-engine/lib/python3.8/site-packages/aiogram/dispatcher/dispatcher.py", line 284, in process_update
    return await self.callback_query_handlers.notify(update.callback_query)
  File "/home/bot/Documents/tb-engine/lib/python3.8/site-packages/aiogram/dispatcher/handler.py", line 116, in notify
    response = await handler_obj.handler(*args, **partial_data)
  File "/home/bot/Documents/test-client-service-bot/handlers/receive_message.py", line 36, in connect_user
    with query.bot.with_token(query.bot.data["send_to_bot_token"]):
  File "/home/bot/Documents/tb-engine/lib/python3.8/site-packages/aiogram/bot/bot.py", line 2187, in get_chat_member
    result = await self.request(api.Methods.GET_CHAT_MEMBER, payload)
  File "/home/bot/Documents/tb-engine/lib/python3.8/site-packages/aiogram/bot/base.py", line 208, in request
    return await api.make_request(self.session, self.server, self.__token, method, data, files,
  File "/home/bot/Documents/tb-engine/lib/python3.8/site-packages/aiogram/bot/api.py", line 140, in make_request
    return check_result(method, response.content_type, response.status, await response.text())
  File "/home/bot/Documents/tb-engine/lib/python3.8/site-packages/aiogram/bot/api.py", line 115, in check_result
    exceptions.BadRequest.detect(description)
  File "/home/bot/Documents/tb-engine/lib/python3.8/site-packages/aiogram/utils/exceptions.py", line 141, in detect
    raise cls(description)
aiogram.utils.exceptions.BadRequest: User not found
2021-10-19 18:46:13,314,__main__[LINE:80] - Bot stopped!
2021-10-19 18:48:42,634,aiogram.dispatcher.dispatcher[LINE:357] - Start polling.
2021-10-19 18:48:42,768,asyncio[LINE:1854] - Executing <Task pending name='Task-3' coro=<start_client_bot() running at /home/bot/Documents/test-client-service-bot/main__.py:47> wait_for=<Future pending cb=[<TaskWakeupMethWrapper object at 0x7fe987ebdaf0>()] created at /usr/lib/python3.8/asyncio/base_events.py:422> cb=[gather.<locals>._done_callback() at /usr/lib/python3.8/asyncio/tasks.py:769] created at /usr/lib/python3.8/asyncio/tasks.py:824> took 0.104 seconds
2021-10-19 18:48:42,949,aiogram.dispatcher.dispatcher[LINE:357] - Start polling.
2021-10-19 18:48:42,968,asyncio[LINE:1854] - Executing <Task pending name='Task-3' coro=<start_client_bot() running at /home/bot/Documents/test-client-service-bot/main__.py:66> wait_for=<Future pending cb=[shield.<locals>._outer_done_callback() at /usr/lib/python3.8/asyncio/tasks.py:902, <TaskWakeupMethWrapper object at 0x7fe987ebd970>()] created at /usr/lib/python3.8/asyncio/base_events.py:422> cb=[gather.<locals>._done_callback() at /usr/lib/python3.8/asyncio/tasks.py:769] created at /usr/lib/python3.8/asyncio/tasks.py:824> took 0.100 seconds
2021-10-19 18:49:45,012,aiogram.dispatcher.dispatcher[LINE:404] - Polling is stopped.
2021-10-19 18:49:45,018,aiogram.dispatcher.dispatcher[LINE:404] - Polling is stopped.
2021-10-19 18:49:45,030,__main__[LINE:82] - Bot stopped!
2021-10-19 18:49:45,451,aiogram.dispatcher.dispatcher[LINE:432] - Stop polling...
2021-10-19 18:49:45,455,aiogram.dispatcher.dispatcher[LINE:432] - Stop polling...
2021-10-19 18:49:51,787,aiogram.dispatcher.dispatcher[LINE:357] - Start polling.
2021-10-19 18:49:51,868,asyncio[LINE:1854] - Executing <Task pending name='Task-2' coro=<start_service_bot() running at /home/bot/Documents/test-client-service-bot/main__.py:30> wait_for=<Future pending cb=[shield.<locals>._outer_done_callback() at /usr/lib/python3.8/asyncio/tasks.py:902, <TaskWakeupMethWrapper object at 0x7f067fa25e80>()] created at /usr/lib/python3.8/asyncio/base_events.py:422> cb=[gather.<locals>._done_callback() at /usr/lib/python3.8/asyncio/tasks.py:769] created at /usr/lib/python3.8/asyncio/tasks.py:824> took 0.197 seconds
2021-10-19 18:49:52,033,asyncio[LINE:1854] - Executing <Task pending name='Task-3' coro=<start_client_bot() running at /home/bot/Documents/test-client-service-bot/main__.py:47> wait_for=<Future pending cb=[<TaskWakeupMethWrapper object at 0x7f067f94cb50>()] created at /usr/lib/python3.8/asyncio/base_events.py:422> cb=[gather.<locals>._done_callback() at /usr/lib/python3.8/asyncio/tasks.py:769] created at /usr/lib/python3.8/asyncio/tasks.py:824> took 0.158 seconds
2021-10-19 18:49:52,226,aiogram.dispatcher.dispatcher[LINE:357] - Start polling.
2021-10-19 18:49:52,276,asyncio[LINE:1854] - Executing <Task pending name='Task-3' coro=<start_client_bot() running at /home/bot/Documents/test-client-service-bot/main__.py:66> wait_for=<Future pending cb=[shield.<locals>._outer_done_callback() at /usr/lib/python3.8/asyncio/tasks.py:902, <TaskWakeupMethWrapper object at 0x7f067e6d3ee0>()] created at /usr/lib/python3.8/asyncio/base_events.py:422> cb=[gather.<locals>._done_callback() at /usr/lib/python3.8/asyncio/tasks.py:769] created at /usr/lib/python3.8/asyncio/tasks.py:824> took 0.129 seconds
2021-10-19 22:10:52,534,aiogram.dispatcher.dispatcher[LINE:404] - Polling is stopped.
2021-10-19 22:10:52,539,aiogram.dispatcher.dispatcher[LINE:404] - Polling is stopped.
2021-10-19 22:10:52,564,__main__[LINE:82] - Bot stopped!
2021-10-19 22:10:52,740,aiogram.dispatcher.dispatcher[LINE:432] - Stop polling...
2021-10-19 22:10:52,741,aiogram.dispatcher.dispatcher[LINE:432] - Stop polling...
2021-10-19 22:10:57,147,aiogram.dispatcher.dispatcher[LINE:357] - Start polling.
2021-10-19 22:10:57,202,aiogram.dispatcher.dispatcher[LINE:357] - Start polling.
2021-10-19 22:36:53,366,aiogram.dispatcher.dispatcher[LINE:404] - Polling is stopped.
2021-10-19 22:36:53,372,aiogram.dispatcher.dispatcher[LINE:404] - Polling is stopped.
2021-10-19 22:36:53,389,__main__[LINE:83] - Bot stopped!
2021-10-19 22:36:53,598,aiogram.dispatcher.dispatcher[LINE:432] - Stop polling...
2021-10-19 22:36:53,600,aiogram.dispatcher.dispatcher[LINE:432] - Stop polling...
2021-10-19 22:37:08,744,aiogram.dispatcher.dispatcher[LINE:357] - Start polling.
2021-10-19 22:37:08,846,aiogram.dispatcher.dispatcher[LINE:357] - Start polling.
2021-10-20 04:10:38,384,aiogram.dispatcher.dispatcher[LINE:389] - Cause exception while getting updates.
Traceback (most recent call last):
  File "/home/bot/Documents/tb-engine/lib/python3.8/site-packages/aiogram/dispatcher/dispatcher.py", line 380, in start_polling
    updates = await self.bot.get_updates(
  File "/home/bot/Documents/tb-engine/lib/python3.8/site-packages/aiogram/bot/bot.py", line 97, in get_updates
    result = await self.request(api.Methods.GET_UPDATES, payload)
  File "/home/bot/Documents/tb-engine/lib/python3.8/site-packages/aiogram/bot/base.py", line 208, in request
    return await api.make_request(self.session, self.server, self.__token, method, data, files,
  File "/home/bot/Documents/tb-engine/lib/python3.8/site-packages/aiogram/bot/api.py", line 140, in make_request
    return check_result(method, response.content_type, response.status, await response.text())
  File "/home/bot/Documents/tb-engine/lib/python3.8/site-packages/aiogram/bot/api.py", line 128, in check_result
    raise exceptions.TelegramAPIError(description)
aiogram.utils.exceptions.TelegramAPIError: Bad Gateway
2021-10-20 08:37:32,842,asyncio[LINE:813] - Getting address info api.telegram.org:443, type=<SocketKind.SOCK_STREAM: 1>, flags=<AddressInfo.AI_ADDRCONFIG: 32> took 111.144ms: [(<AddressFamily.AF_INET: 2>, <SocketKind.SOCK_STREAM: 1>, 6, '', ('149.154.167.220', 443)), (<AddressFamily.AF_INET6: 10>, <SocketKind.SOCK_STREAM: 1>, 6, '', ('2001:67c:4e8:1033:1:100:0:a', 443, 0, 0)), (<AddressFamily.AF_INET6: 10>, <SocketKind.SOCK_STREAM: 1>, 6, '', ('2001:67c:4e8:1033:2:100:0:a', 443, 0, 0)), (<AddressFamily.AF_INET6: 10>, <SocketKind.SOCK_STREAM: 1>, 6, '', ('2001:67c:4e8:1033:3:100:0:a', 443, 0, 0)), (<AddressFamily.AF_INET6: 10>, <SocketKind.SOCK_STREAM: 1>, 6, '', ('2001:67c:4e8:1033:5:100:0:a', 443, 0, 0))]
2021-10-20 09:14:00,379,asyncio[LINE:813] - Getting address info api.telegram.org:443, type=<SocketKind.SOCK_STREAM: 1>, flags=<AddressInfo.AI_ADDRCONFIG: 32> took 236.730ms: [(<AddressFamily.AF_INET: 2>, <SocketKind.SOCK_STREAM: 1>, 6, '', ('149.154.167.220', 443)), (<AddressFamily.AF_INET6: 10>, <SocketKind.SOCK_STREAM: 1>, 6, '', ('2001:67c:4e8:1033:3:100:0:a', 443, 0, 0)), (<AddressFamily.AF_INET6: 10>, <SocketKind.SOCK_STREAM: 1>, 6, '', ('2001:67c:4e8:1033:5:100:0:a', 443, 0, 0)), (<AddressFamily.AF_INET6: 10>, <SocketKind.SOCK_STREAM: 1>, 6, '', ('2001:67c:4e8:1033:2:100:0:a', 443, 0, 0)), (<AddressFamily.AF_INET6: 10>, <SocketKind.SOCK_STREAM: 1>, 6, '', ('2001:67c:4e8:1033:1:100:0:a', 443, 0, 0))]
2021-10-20 10:01:37,563,asyncio[LINE:813] - Getting address info api.telegram.org:443, type=<SocketKind.SOCK_STREAM: 1>, flags=<AddressInfo.AI_ADDRCONFIG: 32> took 124.587ms: [(<AddressFamily.AF_INET: 2>, <SocketKind.SOCK_STREAM: 1>, 6, '', ('149.154.167.220', 443)), (<AddressFamily.AF_INET6: 10>, <SocketKind.SOCK_STREAM: 1>, 6, '', ('2001:67c:4e8:1033:5:100:0:a', 443, 0, 0)), (<AddressFamily.AF_INET6: 10>, <SocketKind.SOCK_STREAM: 1>, 6, '', ('2001:67c:4e8:1033:2:100:0:a', 443, 0, 0)), (<AddressFamily.AF_INET6: 10>, <SocketKind.SOCK_STREAM: 1>, 6, '', ('2001:67c:4e8:1033:1:100:0:a', 443, 0, 0)), (<AddressFamily.AF_INET6: 10>, <SocketKind.SOCK_STREAM: 1>, 6, '', ('2001:67c:4e8:1033:3:100:0:a', 443, 0, 0))]
2021-10-20 10:07:19,178,__main__[LINE:83] - Bot stopped!
2021-10-20 10:07:31,892,aiogram.dispatcher.dispatcher[LINE:357] - Start polling.
2021-10-20 10:07:32,254,aiogram.dispatcher.dispatcher[LINE:357] - Start polling.
2021-10-20 10:07:32,302,asyncio[LINE:813] - Getting address info api.telegram.org:443, type=<SocketKind.SOCK_STREAM: 1>, flags=<AddressInfo.AI_ADDRCONFIG: 32> took 144.483ms: [(<AddressFamily.AF_INET: 2>, <SocketKind.SOCK_STREAM: 1>, 6, '', ('149.154.167.220', 443)), (<AddressFamily.AF_INET6: 10>, <SocketKind.SOCK_STREAM: 1>, 6, '', ('2001:67c:4e8:1033:5:100:0:a', 443, 0, 0)), (<AddressFamily.AF_INET6: 10>, <SocketKind.SOCK_STREAM: 1>, 6, '', ('2001:67c:4e8:1033:2:100:0:a', 443, 0, 0)), (<AddressFamily.AF_INET6: 10>, <SocketKind.SOCK_STREAM: 1>, 6, '', ('2001:67c:4e8:1033:1:100:0:a', 443, 0, 0)), (<AddressFamily.AF_INET6: 10>, <SocketKind.SOCK_STREAM: 1>, 6, '', ('2001:67c:4e8:1033:3:100:0:a', 443, 0, 0))]
2021-10-20 10:27:17,005,__main__[LINE:83] - Bot stopped!
2021-10-20 10:27:28,777,aiogram.dispatcher.dispatcher[LINE:357] - Start polling.
2021-10-20 10:27:28,949,asyncio[LINE:1854] - Executing <Task pending name='Task-3' coro=<start_client_bot() running at /home/bot/Documents/test-client-service-bot/main__.py:48> wait_for=<Future pending cb=[<TaskWakeupMethWrapper object at 0x7fad2d893d30>()] created at /usr/lib/python3.8/asyncio/base_events.py:422> cb=[gather.<locals>._done_callback() at /usr/lib/python3.8/asyncio/tasks.py:769] created at /usr/lib/python3.8/asyncio/tasks.py:824> took 0.144 seconds
2021-10-20 10:27:29,089,aiogram.dispatcher.dispatcher[LINE:357] - Start polling.
2021-10-20 10:39:09,889,asyncio[LINE:1854] - Executing <Task pending name='Task-3' coro=<start_client_bot() running at /home/bot/Documents/test-client-service-bot/main__.py:67> wait_for=<Future pending cb=[<TaskWakeupMethWrapper object at 0x7fad2c501190>()] created at /usr/lib/python3.8/asyncio/base_events.py:422> cb=[gather.<locals>._done_callback() at /usr/lib/python3.8/asyncio/tasks.py:769] created at /usr/lib/python3.8/asyncio/tasks.py:824> took 0.262 seconds
2021-10-20 10:57:12,657,handlers.fsm_add_event[LINE:78] - enter to process_media func
2021-10-20 11:15:58,239,aiogram.dispatcher.dispatcher[LINE:404] - Polling is stopped.
2021-10-20 11:15:58,262,aiogram.dispatcher.dispatcher[LINE:404] - Polling is stopped.
2021-10-20 11:15:58,276,__main__[LINE:83] - Bot stopped!
2021-10-20 11:15:58,538,aiogram.dispatcher.dispatcher[LINE:432] - Stop polling...
2021-10-20 11:15:58,538,aiogram.dispatcher.dispatcher[LINE:432] - Stop polling...
2021-10-20 11:16:03,842,aiogram.dispatcher.dispatcher[LINE:357] - Start polling.
2021-10-20 11:16:03,874,asyncio[LINE:1854] - Executing <Task pending name='Task-2' coro=<start_service_bot() running at /home/bot/Documents/test-client-service-bot/main__.py:31> wait_for=<Future pending cb=[shield.<locals>._outer_done_callback() at /usr/lib/python3.8/asyncio/tasks.py:902, <TaskWakeupMethWrapper object at 0x7f0fc63ac460>()] created at /usr/lib/python3.8/asyncio/base_events.py:422> cb=[gather.<locals>._done_callback() at /usr/lib/python3.8/asyncio/tasks.py:769] created at /usr/lib/python3.8/asyncio/tasks.py:824> took 0.122 seconds
2021-10-20 11:16:04,007,asyncio[LINE:1854] - Executing <Task pending name='Task-3' coro=<start_client_bot() running at /home/bot/Documents/test-client-service-bot/main__.py:48> wait_for=<Future pending cb=[<TaskWakeupMethWrapper object at 0x7f0fc63460d0>()] created at /usr/lib/python3.8/asyncio/base_events.py:422> cb=[gather.<locals>._done_callback() at /usr/lib/python3.8/asyncio/tasks.py:769] created at /usr/lib/python3.8/asyncio/tasks.py:824> took 0.133 seconds
2021-10-20 11:16:04,215,aiogram.dispatcher.dispatcher[LINE:357] - Start polling.
2021-10-20 11:16:04,234,asyncio[LINE:1854] - Executing <Task pending name='Task-3' coro=<start_client_bot() running at /home/bot/Documents/test-client-service-bot/main__.py:67> wait_for=<Future pending cb=[shield.<locals>._outer_done_callback() at /usr/lib/python3.8/asyncio/tasks.py:902, <TaskWakeupMethWrapper object at 0x7f0fc514d850>()] created at /usr/lib/python3.8/asyncio/base_events.py:422> cb=[gather.<locals>._done_callback() at /usr/lib/python3.8/asyncio/tasks.py:769] created at /usr/lib/python3.8/asyncio/tasks.py:824> took 0.151 seconds
2021-10-20 12:21:33,614,asyncio[LINE:1854] - Executing <Task pending name='Task-2' coro=<start_service_bot() running at /home/bot/Documents/test-client-service-bot/main__.py:31> wait_for=<Future pending cb=[<TaskWakeupMethWrapper object at 0x7f0fc6492b20>()] created at /usr/lib/python3.8/asyncio/base_events.py:422> cb=[gather.<locals>._done_callback() at /usr/lib/python3.8/asyncio/tasks.py:769] created at /usr/lib/python3.8/asyncio/tasks.py:824> took 0.313 seconds
